<?xml version="1.0" ?> 
<!--================================================================== -->
<!--This document was modified and tested for its correctness        -->
<!--EDITING THIS FILE BY HAND IS NOT RECOMMENDED                     -->
<!--=================================================================== -->
<robot name="arm_description" xmlns:xacro="http://www.ros.org/wiki/xacro">
  <link name="world"/>
  <joint name="world_joint" type="fixed">
    <origin rpy="0 0 0" xyz="0 0 0.04"/>
    <parent link="world"/>
    <child link="base_link"/>
  </joint>
  <!-- ////  base link -> shoulder link  ////-->
  <link name="base_link">
    <visual>
      <origin rpy="0 0 0" xyz="0 0 0"/>
      <geometry>
        <cylinder length="0.04" radius="0.05"/>
      </geometry>
    </visual>
    <collision>
      <origin rpy="0 0 0" xyz="0 0 0"/>
      <geometry>
        <cylinder length="0.04" radius="0.05"/>
      </geometry>
    </collision>
    <inertial>
      <mass value="0.1"/>
      <inertia ixx="1.0" ixy="0.0" ixz="0.0" iyy="0.5" iyz="0.0" izz="1.0"/>
    </inertial>
  </link>
  <joint name="base_joint" type="revolute">
    <parent link="base_link"/>
    <child link="shoulder_link"/>
    <origin rpy="0 0 0" xyz="0 0 0.025"/>
    <axis xyz="0 0 1"/>
    <limit effort="300" lower="-1.570795" upper="1.570795" velocity="1"/>
    <dynamics damping="50" friction="1"/>
  </joint>
  <!-- ////  shoulder link -> elbow link  ////-->
  <link name="shoulder_link">
    <visual>
      <origin rpy="0 0 0" xyz="0 0 0"/>
      <geometry>
        <cylinder length="0.002" radius="0.04"/>
      </geometry>
    </visual>
    <collision>
      <origin rpy="0 0 0" xyz="0 0 0"/>
      <geometry>
        <cylinder length="0.002" radius="0.04"/>
      </geometry>
    </collision>
    <inertial>
      <mass value="0.1"/>
      <inertia ixx="1.0" ixy="0.0" ixz="0.0" iyy="0.5" iyz="0.0" izz="1.0"/>
    </inertial>
  </link>
  <joint name="shoulder_joint" type="revolute">
    <parent link="shoulder_link"/>
    <child link="elbow_link"/>
    <origin rpy="0 0 0" xyz="0 0 0.006"/>
    <axis xyz="0 -1 0"/>
    <limit effort="300" lower="-1.4835298642" upper="1.4835298642" velocity="1"/>
    <dynamics damping="50" friction="1"/>
  </joint>
  <!-- ////  elbow link -> wrist flex link  ////-->
  <link name="elbow_link">
    <visual>
      <origin rpy="0 0 0" xyz="0 0 0.045"/>
      <geometry>
        <box size="0.015 0.04 0.1"/>
      </geometry>
    </visual>
    <collision>
      <origin rpy="0 0 0" xyz="0 0 0.045"/>
      <geometry>
        <box size="0.015 0.04 0.1"/>
      </geometry>
    </collision>
    <inertial>
      <mass value="0.1"/>
      <inertia ixx="1.0" ixy="0.0" ixz="0.0" iyy="0.5" iyz="0.0" izz="1.0"/>
    </inertial>
  </link>
  <joint name="elbow_joint" type="revolute">
    <parent link="elbow_link"/>
    <child link="wrist_flex_link"/>
    <origin rpy="0 0 0" xyz="0 0 0.09"/>
    <axis xyz="0 1 0"/>
    <limit effort="300" lower="-1.0471975512" upper="1.57079632679" velocity="1"/>
    <dynamics damping="50" friction="1"/>
  </joint>
  <!-- ////  wrist flex link -> wrist rot link  ////-->
  <link name="wrist_flex_link">
    <visual>
      <origin rpy="0 0 0" xyz="0 0 0.045"/>
      <geometry>
        <box size="0.015 0.035 0.1"/>
      </geometry>
    </visual>
    <collision>
      <origin rpy="0 0 0" xyz="0 0 0.045"/>
      <geometry>
        <box size="0.015 0.035 0.1"/>
      </geometry>
    </collision>
    <inertial>
      <mass value="0.1"/>
      <inertia ixx="1.0" ixy="0.0" ixz="0.0" iyy="0.5" iyz="0.0" izz="1.0"/>
    </inertial>
  </link>
  <joint name="wrist_flex_joint" type="revolute">
    <parent link="wrist_flex_link"/>
    <child link="wrist_rot_link"/>
    <origin rpy="0 0 0" xyz="0 0 0.09"/>
    <axis xyz="0 1 0"/>
    <limit effort="300" lower="-1.570795" upper="0" velocity="1"/>
    <dynamics damping="50" friction="1"/>
  </joint>
  <!-- ////  wrist rot link -> gripper link  ////-->
  <link name="wrist_rot_link">
    <visual>
      <origin rpy="0 0 0" xyz="0.01 0 0.01"/>
      <geometry>
        <box size="0.025 0.025 0.025"/>
      </geometry>
    </visual>
    <collision>
      <origin rpy="0 0 0" xyz="0.01 0 0.01"/>
      <geometry>
        <box size="0.025 0.025 0.025"/>
      </geometry>
    </collision>
    <inertial>
      <mass value="0.1"/>
      <inertia ixx="1.0" ixy="0.0" ixz="0.0" iyy="0.5" iyz="0.0" izz="1.0"/>
    </inertial>
  </link>
  <joint name="wrist_rot_joint" type="revolute">
    <parent link="wrist_rot_link"/>
    <child link="gripper_bottom_link"/>
    <origin rpy="0 0 0" xyz="0.02 0.008 0.0225"/>
    <axis xyz="0 0 1"/>
    <limit effort="300" lower="-1.570795" upper="0" velocity="1"/>
    <dynamics damping="50" friction="1"/>
  </joint>
  <!-- ////  wrist rot link -> gripper bottom link  ////-->
  <link name="gripper_bottom_link">
    <visual>
      <origin rpy="0 0 0" xyz="0 0 0.005"/>
      <geometry>
        <box size="0.003 0.01 0.01"/>
      </geometry>
      <material name="Red"/>
    </visual>
    <collision>
      <origin rpy="0 0 0" xyz="0 0 0.005"/>
      <geometry>
        <box size="0.003 0.01 0.01"/>
      </geometry>
    </collision>
    <inertial>
      <mass value="0.1"/>
      <inertia ixx="1.0" ixy="0.0" ixz="0.0" iyy="0.5" iyz="0.0" izz="1.0"/>
    </inertial>
  </link>
  <joint name="gripper_attach_joint" type="fixed">
    <parent link="gripper_bottom_link"/>
    <child link="gripper_link"/>
    <origin rpy="0 0 0" xyz="0 0 0.01"/>
  </joint>
  <!-- ////  gripper link  ////-->
  <link name="gripper_link">
    <visual>
      <origin rpy="0 0 0" xyz="0 0 0.002"/>
      <geometry>
        <box size="0.01 0.035 0.004"/>
      </geometry>
      <material name="Red"/>
    </visual>
    <collision>
      <origin rpy="0 0 0" xyz="0 0 0.002"/>
      <geometry>
        <box size="0.01 0.035 0.004"/>
      </geometry>
    </collision>
    <inertial>
      <mass value="0.1"/>
      <inertia ixx="1.0" ixy="0.0" ixz="0.0" iyy="0.5" iyz="0.0" izz="1.0"/>
    </inertial>
  </link>
  <!-- ////  gripper link -> gripper finger link1  ////-->
  <joint name="finger_joint1" type="prismatic">
    <parent link="gripper_link"/>
    <child link="gripper_finger_link1"/>
    <origin xyz="0 0 0.002"/>
    <axis xyz="0 1 0"/>
    <limit effort="200" lower="-0.015" upper="0" velocity="1.0"/>
    <dynamics damping="50" friction="1"/>
  </joint>
  <link name="gripper_finger_link1">
    <visual>
      <origin xyz="0 0.016 0.03"/>
      <geometry>
        <box size="0.01 0.002 0.06"/>
      </geometry>
    </visual>
    <collision>
      <origin xyz="0 0.016 0.03"/>
      <geometry>
        <box size="0.01 0.002 0.06"/>
      </geometry>
    </collision>
    <inertial>
      <mass value="0.1"/>
      <inertia ixx="1.0" ixy="0.0" ixz="0.0" iyy="0.5" iyz="0.0" izz="1.0"/>
    </inertial>
  </link>
  <!-- ////  gripper link -> gripper finger link2  ////-->
  <joint name="finger_joint2" type="prismatic">
    <parent link="gripper_link"/>
    <child link="gripper_finger_link2"/>
    <origin xyz="0 0 0.002"/>
    <axis xyz="0 1 0"/>
    <limit effort="200" lower="0" upper="0.015" velocity="1.0"/>
    <dynamics damping="50" friction="1"/>
  </joint>
  <link name="gripper_finger_link2">
    <visual>
      <origin xyz="0 -0.016 0.03"/>
      <geometry>
        <box size="0.01 0.002 0.06"/>
      </geometry>
    </visual>
    <collision>
      <origin xyz="0 -0.016 0.03"/>
      <geometry>
        <box size="0.01 0.002 0.06"/>
      </geometry>
    </collision>
    <inertial>
      <mass value="0.1"/>
      <inertia ixx="1.0" ixy="0.0" ixz="0.0" iyy="0.5" iyz="0.0" izz="1.0"/>
    </inertial>
  </link>
  <!-- ////  gripper link -> grasp frame link  ////-->
  <link name="grasp_frame_link">
    <inertial>
      <origin rpy="0 0 0" xyz="0 0 0"/>
      <mass value="0.0001"/>
      <cuboid_inertia mass="0.0001" x="0.001" y="0.001" z="0.001"/>
      <inertia ixx="1.0" ixy="0.0" ixz="0.0" iyy="10.0" iyz="0.0" izz="1.0"/>
    </inertial>
    <!--visual>
            <origin xyz="0 0 0"/>
            <geometry>
                <box size="0.01 0.01 0.01"/>
            </geometry>
        </visual-->
  </link>
  <joint name="grasp_frame_joint" type="fixed">
    <parent link="gripper_link"/>
    <child link="grasp_frame_link"/>
    <origin rpy="0 0 0" xyz="0 0 0.065"/>
    <!--limit effort="300" velocity="1" lower="0" upper="0"/-->
  </joint>
  <!-- 
    <xacro:base name="base"/>
    <xacro:arm parent="base"/>
    <xacro:gripper parent="tool"/>
    -->
</robot>

